<?xml version="1.0"?>
<robot name="lgdxrobot2" xmlns:xacro="http://ros.org/wiki/xacro">

  <!-- Define robot constants -->
  <xacro:property name="base_width" value="0.237"/>
  <xacro:property name="base_length" value="0.286"/>
  <xacro:property name="base_height" value="0.08"/>
  <xacro:property name="wheel_radius" value="0.0375"/>
  <xacro:property name="wheel_width" value="0.031"/>

  <!-- Define base centre to wheel centre -->
  <xacro:property name="wheel_xoff" value="0.10075"/>
  <xacro:property name="wheel_yoff" value="0.103"/>
  <xacro:property name="wheel_zoff" value="0.0585"/>

  <!-- Define Camera constants -->
  <xacro:property name="camera_width" value="0.09"/>
  <xacro:property name="camera_length" value="0.025"/>
  <xacro:property name="camera_height" value="0.025"/>

  <!-- Define camera centre to wheel centre -->
  <xacro:property name="camera_xoff" value="0.1345"/>
  <xacro:property name="camera_yoff" value="-0.008"/>
  <xacro:property name="camera_zoff" value="0.0165"/>

  <!-- Define camera TF centre to camera centre -->
  <!-- Intel Realsense uses infra1 as the camera_link which is not centre of the camera, check datasheet for details -->
  <xacro:property name="camera_centre_xoff" value="0.0083"/> <!-- D435i = 25mm / 2 - 4.2mm -->
  <xacro:property name="camera_centre_yoff" value="0.0175"/> <!-- D435i = 17.5mm -->
  <xacro:property name="camera_centre_zoff" value="0.0"/>

  <!-- Define intertial property macros  -->
  <xacro:macro name="box_inertia" params="m w h d">
    <inertial>
      <origin xyz="0 0 0" rpy="${pi/2} 0 ${pi/2}"/>
      <mass value="${m}"/>
      <inertia ixx="${(m/12) * (h*h + d*d)}" ixy="0.0" ixz="0.0" iyy="${(m/12) * (w*w + d*d)}" iyz="0.0" izz="${(m/12) * (w*w + h*h)}"/>
    </inertial>
  </xacro:macro>

  <xacro:macro name="cylinder_inertia" params="m r h">
    <inertial>
      <origin xyz="0 0 0" rpy="${pi/2} 0 0" />
      <mass value="${m}"/>
      <inertia ixx="${(m/12) * (3*r*r + h*h)}" ixy = "0" ixz = "0" iyy="${(m/12) * (3*r*r + h*h)}" iyz = "0" izz="${(m/2) * (r*r)}"/>
    </inertial>
  </xacro:macro>

  <!-- Robot Base -->
  <link name="base_link">
    <visual>
      <geometry>
        <box size="${base_length} ${base_width} ${base_height}"/>
      </geometry>
      <material name="LGDXRed">
        <color rgba="0.50196078431 0.09803921568 0.11764705882 1.0"/>
      </material>
    </visual>

    <collision>
      <geometry>
        <box size="${base_length} ${base_width} ${base_height}"/>
      </geometry>
    </collision>

    <xacro:box_inertia m="3" w="${base_width}" d="${base_length}" h="${base_height}"/>
  </link>

  <!-- Robot Footprint -->
  <link name="base_footprint"/>

  <joint name="base_joint" type="fixed">
    <parent link="base_link"/>
    <child link="base_footprint"/>
    <origin xyz="0.0 0.0 ${-(wheel_radius+wheel_zoff)}" rpy="0 0 0"/>
  </joint>

  <!-- Wheels -->
  <xacro:macro name="wheel" params="prefix x_reflect y_reflect">
    <link name="${prefix}_link">
      <visual>
        <origin xyz="0 0 0" rpy="${pi/2} 0 0"/>
        <geometry>
            <cylinder radius="${wheel_radius}" length="${wheel_width}"/>
        </geometry>
        <material name="LGDXBlack">
          <color rgba="0 0 0 1.0"/>
        </material>
      </visual>

      <collision>
        <origin xyz="0 0 0" rpy="${pi/2} 0 0"/>
        <geometry>
          <cylinder radius="${wheel_radius}" length="${wheel_width}"/>
        </geometry>
      </collision>

      <xacro:cylinder_inertia m="0.2" r="${wheel_radius}" h="${wheel_width}"/>
    </link>

    <joint name="${prefix}_joint" type="continuous">
      <parent link="base_link"/>
      <child link="${prefix}_link"/>
      <origin xyz="${x_reflect*wheel_xoff} ${y_reflect*wheel_yoff} ${-wheel_zoff}" rpy="0 0 0"/>
      <axis xyz="0 1 0"/>
    </joint>
  </xacro:macro>

  <xacro:wheel prefix="drive_m1" x_reflect="1" y_reflect="1" />
  <xacro:wheel prefix="drive_m2" x_reflect="1" y_reflect="-1" />
  <xacro:wheel prefix="drive_m3" x_reflect="-1" y_reflect="1" />
  <xacro:wheel prefix="drive_m4" x_reflect="-1" y_reflect="-1" />

  <!-- Camera  -->
  <link name="camera_centre_link">
    <visual>
      <geometry>
        <box size="${camera_length} ${camera_width} ${camera_height}"/>
      </geometry>
      <material name="LGDXBlack">
        <color rgba="0 0 0 1.0"/>
      </material>
    </visual>

    <collision>
      <geometry>
        <box size="${camera_length} ${camera_width} ${camera_height}"/>
      </geometry>
    </collision>

    <xacro:box_inertia m="0.1" w="${camera_width}" d="${camera_length}" h="${camera_height}"/>
  </link>

  <joint name="camera_joint" type="fixed">
    <parent link="base_link"/>
    <child link="camera_centre_link"/>
    <origin xyz="${camera_xoff} ${camera_yoff} ${camera_zoff}"/>
  </joint>

  <link name="camera_link" />
  <joint name="camera_centre_joint" type="fixed">
    <parent link="camera_centre_link"/>
    <child link="camera_link"/>
    <origin xyz="${camera_centre_xoff} ${camera_centre_yoff} ${camera_centre_zoff}"/>
  </joint>
</robot>