<?xml version="1.0" ?>
<robot name="lgdxrobot2" xmlns:xacro="http://www.ros.org/wiki/xacro" xmlns:gz="http://gazebosim.org/schema">
  <joint name="base_footprint_joint" type="fixed">
    <origin rpy="0.00000 0.00000 0.00000" xyz="0.00000 0.00000 0.00000"/>
    <parent link="base_link"/>
    <child link="base_footprint"/>
  </joint>
  <joint name="camera_link_joint" type="fixed">
    <origin rpy="0.00000 0.00000 0.00000" xyz="0.13104 0.01776 0.07181"/>
    <parent link="base_link"/>
    <child link="camera_link"/>
  </joint>
  <joint name="camera_color_frame_joint" type="fixed">
    <origin rpy="0.00000 0.00000 0.00000" xyz="-0.00000 0.01500 0.00000"/>
    <parent link="camera_link"/>
    <child link="camera_color_frame"/>
  </joint>
  <joint name="camera_depth_frame_joint" type="fixed">
    <origin rpy="0.00000 0.00000 0.00000" xyz="-0.00000 -0.00000 0.00000"/>
    <parent link="camera_link"/>
    <child link="camera_depth_frame"/>
  </joint>
  <joint name="imu_link_joint" type="fixed">
    <origin rpy="0.00000 0.00000 0.00000" xyz="-0.08351 0.00000 0.0649"/>
    <parent link="base_link"/>
    <child link="imu_link"/>
  </joint>
  <joint name="lidar_link_joint" type="fixed">
    <origin rpy="0.00000 0.00000 -3.14159" xyz="0.06000 -0.00000 0.15641"/>
    <parent link="base_link"/>
    <child link="lidar_link"/>
  </joint>
  <joint name="wheel1_link_joint" type="continuous">
    <limit effort="10000" velocity="10"/>
    <dynamics damping="1.0" friction="1.0"/>
    <origin rpy="-1.57080 0.00000 0.00000" xyz="0.08200 0.10357 0.03681"/>
    <parent link="base_link"/>
    <child link="wheel1_link"/>
    <axis xyz="0 0 1" rpy="0 0 0"/>
  </joint>
  <joint name="wheel2_link_joint" type="continuous">
    <limit effort="10000" velocity="10"/>
    <dynamics damping="1.0" friction="1.0"/>
    <origin rpy="-1.57080 0.00000 0.00000" xyz="0.08200 -0.10357 0.03681"/>
    <parent link="base_link"/>
    <child link="wheel2_link"/>
    <axis xyz="0 0 1" rpy="0 0 0"/>
  </joint>
  <joint name="wheel3_link_joint" type="continuous">
    <limit effort="10000" velocity="10"/>
    <dynamics damping="1.0" friction="1.0"/>
    <origin rpy="-1.57080 0.00000 0.00000" xyz="-0.08200 0.10357 0.03681"/>
    <parent link="base_link"/>
    <child link="wheel3_link"/>
    <axis xyz="0 0 1" rpy="0 0 0"/>
  </joint>
  <joint name="wheel4_link_joint" type="continuous">
    <limit effort="10000" velocity="10"/>
    <dynamics damping="1.0" friction="1.0"/>
    <origin rpy="-1.57080 0.00000 0.00000" xyz="-0.08200 -0.10357 0.03681"/>
    <parent link="base_link"/>
    <child link="wheel4_link"/>
    <axis xyz="0 0 1" rpy="0 0 0"/>
  </joint>
  <link name="base_link">
    <collision name="plates_collision">
      <origin rpy="0.00000 0.00000 0.00000" xyz="0.00000 0.00000 0.09400"/>
      <geometry>
        <box size="0.24000 0.24000 0.07800"/>
      </geometry>
    </collision>
    <visual name="board">
      <material name="lgdxrobot_green"/>
      <origin rpy="0.00000 0.00000 0.00000" xyz="0.00000 0.00000 0.00000"/>
      <geometry>
        <mesh filename="package://lgdxrobot2_description/meshes/dae/b_LGDXRobot2_Board_001_.dae" scale="1.00000 1.00000 1.00000"/>
      </geometry>
    </visual>
    <visual name="brackets">
      <material name="lgdxrobot_black"/>
      <origin rpy="0.00000 0.00000 0.00000" xyz="0.00000 0.00000 0.00000"/>
      <geometry>
        <mesh filename="package://lgdxrobot2_description/meshes/dae/b_Mounting_Bracket_001_001.dae" scale="1.00000 1.00000 1.00000"/>
      </geometry>
    </visual>
    <visual name="motors">
      <material name="lgdxrobot_sliver"/>
      <origin rpy="0.00000 0.00000 0.00000" xyz="0.00000 0.00000 0.00000"/>
      <geometry>
        <mesh filename="package://lgdxrobot2_description/meshes/dae/b_Motor_001_001.dae" scale="1.00000 1.00000 1.00000"/>
      </geometry>
    </visual>
    <visual name="plates">
      <material name="lgdxrobot_red"/>
      <origin rpy="0.00000 0.00000 0.00000" xyz="0.00000 0.00000 0.00000"/>
      <geometry>
        <mesh filename="package://lgdxrobot2_description/meshes/dae/b_Top_Plate_001_.dae" scale="1.00000 1.00000 1.00000"/>
      </geometry>
    </visual>
    <visual name="screws">
      <material name="lgdxrobot_sliver"/>
      <origin rpy="0.00000 0.00000 0.00000" xyz="0.00000 0.00000 0.00000"/>
      <geometry>
        <mesh filename="package://lgdxrobot2_description/meshes/dae/b_M4_Nut_001_021.dae" scale="1.00000 1.00000 1.00000"/>
      </geometry>
    </visual>
    <visual name="standoffs">
      <material name="lgdxrobot_sliver"/>
      <origin rpy="0.00000 0.00000 0.00000" xyz="0.00000 0.00000 0.00000"/>
      <geometry>
        <mesh filename="package://lgdxrobot2_description/meshes/dae/b_Coupling_Nut_70mm_001_006.dae" scale="1.00000 1.00000 1.00000"/>
      </geometry>
    </visual>
    <inertial>
      <mass value="2.2768"/>
      <origin xyz="0.0 0 0" rpy=" 0 0 0"/>
      <inertia
          ixx="0.0625" ixy="0" ixz="0"
          iyy="0.2125" iyz="0"
          izz="0.25"
      />
    </inertial>
  </link>
  <link name="base_footprint"/>
  <link name="camera_link">
    <collision name="camera_collision">
      <origin rpy="0.00000 0.00000 0.00000" xyz="0.01097 -0.00000 0.01306"/>
      <geometry>
        <box size="0.02500 0.09000 0.02500"/>
      </geometry>
    </collision>
    <visual name="camera">
      <material name="lgdxrobot_sliver"/>
      <origin rpy="0.00000 0.00000 0.00000" xyz="-0.02304 -0.01750 -0.01250"/>
      <geometry>
        <mesh filename="package://lgdxrobot2_description/meshes/dae/b_Camera_001_.dae" scale="1.00000 1.00000 1.00000"/>
      </geometry>
    </visual>
  </link>
  <link name="camera_color_frame"/>
  <link name="camera_depth_frame"/>
  <link name="imu_link"/>
  <link name="lidar_link">
    <collision name="lidar_collision">
      <origin rpy="0.00000 0.00000 0.00000" xyz="0.00000 -0.00000 0.02150"/>
      <geometry>
        <box size="0.05560 0.05560 0.04130"/>
      </geometry>
    </collision>
    <visual name="lidar">
      <material name="lgdxrobot_black"/>
      <origin rpy="0.00000 0.00000 0.00000" xyz="0.00000 -0.00000 -0.02310"/>
      <geometry>
        <mesh filename="package://lgdxrobot2_description/meshes/dae/b_Lidar_001_.dae" scale="1.00000 1.00000 1.00000"/>
      </geometry>
    </visual>
  </link>
  <link name="wheel1_link">
    <inertial>
      <mass value="0.1018"/>
      <origin xyz="0 0 0" rpy="0 0 0"/>
      <inertia
          ixx="0.00004448" ixy="0" ixz="0"
          iyy="0.00004448" iyz="0"
          izz="0.00007158"
      />
    </inertial>

    <collision>
      <geometry>
        <sphere radius="0.0375"/>
      </geometry>
    </collision>

    <visual name='wheel1'>
      <material name="lgdxrobot_black"/>
      <origin xyz="0 0 0" rpy="1.5707 0 0"/>
      <geometry>
        <mesh filename="package://lgdxrobot2_description/meshes/dae/b_Wheel_1_001_.dae" scale="1.00000 1.00000 1.00000"/>
      </geometry>
    </visual>
  </link>
  <link name="wheel2_link">
    <inertial>
      <mass value="0.1018"/>
      <origin xyz="0 0 0" rpy="0 0 0"/>
      <inertia
          ixx="0.00004448" ixy="0" ixz="0"
          iyy="0.00004448" iyz="0"
          izz="0.00007158"
      />
    </inertial>

    <collision>
      <geometry>
        <sphere radius="0.0375"/>
      </geometry>
    </collision>

    <visual name='wheel2'>
      <origin xyz="0 0 0" rpy="1.5707 0 0"/>
      <material name="lgdxrobot_black"/>
      <geometry>
        <mesh filename="package://lgdxrobot2_description/meshes/dae/b_Wheel_2_001_.dae" scale="1.00000 1.00000 1.00000"/>
      </geometry>
    </visual>
  </link>
  <link name="wheel3_link">
    <inertial>
      <mass value="0.1018"/>
      <origin xyz="0 0 0" rpy="0 0 0"/>
      <inertia
          ixx="0.00004448" ixy="0" ixz="0"
          iyy="0.00004448" iyz="0"
          izz="0.00007158"
      />
    </inertial>

    <collision>
      <geometry>
        <sphere radius="0.0375"/>
      </geometry>
    </collision>

    <visual name='wheel3'>
      <material name="lgdxrobot_black"/>

      <origin xyz="0 0 0" rpy="1.5707 0 0"/>
      <geometry>
        <mesh filename="package://lgdxrobot2_description/meshes/dae/b_Wheel_3_001_.dae" scale="1.00000 1.00000 1.00000"/>
      </geometry>
    </visual>
  </link>
  <link name="wheel4_link">
    <inertial>
      <mass value="0.1018"/>
      <origin xyz="0 0 0" rpy="0 0 0"/>
      <inertia
          ixx="0.00004448" ixy="0" ixz="0"
          iyy="0.00004448" iyz="0"
          izz="0.00007158"
      />
    </inertial>

    <collision>
      <geometry>
        <sphere radius="0.0375"/>
      </geometry>
    </collision>

    <visual name='wheel4'>
      <material name="lgdxrobot_black"/>
      <origin xyz="0 0 0" rpy="1.5707 0 0"/>
      <geometry>
        <mesh filename="package://lgdxrobot2_description/meshes/dae/b_Wheel_4_001_.dae" scale="1.00000 1.00000 1.00000"/>
      </geometry>
    </visual>
  </link>
  <!-- Gazebo MecanumDrive -->
  <gazebo>
    <plugin
      filename="gz-sim-mecanum-drive-system"
      name="gz::sim::systems::MecanumDrive">
      <topic>cmd_vel</topic>
      <front_left_joint>wheel1_link_joint</front_left_joint>
      <front_right_joint>wheel2_link_joint</front_right_joint>
      <back_left_joint>wheel3_link_joint</back_left_joint>
      <back_right_joint>wheel4_link_joint</back_right_joint>
      <wheel_separation>0.208</wheel_separation>
      <wheelbase>0.164</wheelbase>
      <wheel_radius>0.0375</wheel_radius>
      <min_acceleration>-5</min_acceleration>
      <max_acceleration>5</max_acceleration>
      <odom_topic>odom</odom_topic>
      <tf_topic>tf</tf_topic>
      <frame_id>odom</frame_id>
      <child_frame_id>base_link</child_frame_id>
      <odom_publish_frequency>100</odom_publish_frequency>
    </plugin>
    <plugin
      filename="gz-sim-joint-state-publisher-system"
      name="gz::sim::systems::JointStatePublisher">
      <topic>joint_states</topic>
    </plugin>
  </gazebo>
  <gazebo reference='wheel1_link'>
    <collision>
      <surface>
        <friction>
          <ode>
            <mu>1.5</mu>
            <mu2>0.0</mu2>
            <fdir1 gz:expressed_in="base_link">1 -1 0</fdir1>
          </ode>
        </friction>
      </surface>
    </collision>
  </gazebo>
  <gazebo reference='wheel3_link'>
    <collision>
      <surface>
        <friction>
          <ode>
            <mu>1.5</mu>
            <mu2>0.0</mu2>
            <fdir1 gz:expressed_in="base_link">1 1 0</fdir1>
          </ode>
        </friction>
      </surface>
    </collision>
  </gazebo>
  <gazebo reference='wheel2_link'>
    <collision>
      <surface>
        <friction>
          <ode>
            <mu>1.5</mu>
            <mu2>0.0</mu2>
            <fdir1 gz:expressed_in="base_link">1 1 0</fdir1>
          </ode>
        </friction>
      </surface>
    </collision>
  </gazebo>
  <gazebo reference='wheel4_link'>
    <collision>
      <surface>
        <friction>
          <ode>
            <mu>1.5</mu>
            <mu2>0.0</mu2>
            <fdir1 gz:expressed_in="base_link">1 -1 0</fdir1>
          </ode>
        </friction>
      </surface>
    </collision>
  </gazebo>
  <gazebo reference="base_link">
    <mu1>0.000002</mu1>
    <mu2>0.000002</mu2>
  </gazebo>
  <!-- Gazebo LiDAR -->
  <gazebo>
   <plugin
      filename="gz-sim-sensors-system"
      name="gz::sim::systems::Sensors">
      <render_engine>ogre2</render_engine>
    </plugin>
  </gazebo>
  <gazebo reference="lidar_link">
    <sensor name='lidar' type='gpu_lidar'>"
      <pose relative_to='lidar_link'>0 0 0 0 0 0</pose>
      <topic>scan</topic>
      <gz_frame_id>lidar_link</gz_frame_id>
      <update_rate>10</update_rate>
      <ray>
        <scan>
          <horizontal>
            <samples>500</samples>
            <resolution>1</resolution>
            <min_angle>-3.14159265359</min_angle>
            <max_angle>3.14159265359</max_angle>
          </horizontal>
          <vertical>
            <samples>1</samples>
            <resolution>0.01</resolution>
            <min_angle>0</min_angle>
            <max_angle>0</max_angle>
          </vertical>
        </scan>
        <range>
          <min>0.08</min>
          <max>10.0</max>
          <resolution>0.05</resolution>
        </range>
      </ray>
      <always_on>1</always_on>
      <visualize>true</visualize>
    </sensor>
  </gazebo>
  <!-- Gazebo IMU -->
  <gazebo>
    <plugin filename="gz-sim-imu-system"
      name="gz::sim::systems::Imu">
    </plugin>
  </gazebo>
  <gazebo reference="imu_link">
    <sensor name="imu" type="imu">
      <always_on>1</always_on>
      <update_rate>100</update_rate>
      <visualize>true</visualize>
      <topic>imu</topic>
      <gz_frame_id>imu_link</gz_frame_id>
    </sensor>
  </gazebo>
  <!-- Gazebo Camera -->
  <gazebo reference="camera_color_frame">
    <sensor name="camera" type="camera">
      <always_on>1</always_on>
      <update_rate>30</update_rate>
      <visualize>true</visualize>
      <topic>camera/color/image_raw</topic>
      <gz_frame_id>camera_color_frame</gz_frame_id>
      <camera_info_topic>camera/color/camera_info</camera_info_topic>
      <camera name="camera_color">
        <horizontal_fov>1.047198</horizontal_fov>
        <image>
          <width>1280</width>
          <height>720</height>
          <format>R8G8B8</format>
        </image>
        <clip>
          <near>0.1</near>
          <far>100</far>
        </clip>
      </camera>
    </sensor>
  </gazebo>
  <gazebo reference="camera_depth_frame">
    <sensor name="depth_camera" type="depth">
      <always_on>1</always_on>
      <update_rate>30</update_rate>
      <visualize>true</visualize>
      <topic>camera/depth/image_rect_raw</topic>
      <gz_frame_id>camera_depth_frame</gz_frame_id>
      <camera_info_topic>camera/depth/camera_info</camera_info_topic>
      <depth_camera name="camera_depth">
        <horizontal_fov>1.047198</horizontal_fov>
        <image>
          <width>1280</width>
          <height>720</height>
        </image>
        <clip>
          <near>0.3</near>
          <far>3</far>
        </clip>
        <output>depth</output>
      </depth_camera>
    </sensor>
  </gazebo>
  <material name="lgdxrobot_black">
    <color rgba="0.00000 0.00000 0.00000 1.00000"/>
  </material>
  <material name="lgdxrobot_green">
    <color rgba="0.00000 0.25882 0.06667 1.00000"/>
  </material>
  <material name="lgdxrobot_red">
    <color rgba="0.21961 0.00784 0.01176 1.00000"/>
  </material>
  <material name="lgdxrobot_sliver">
    <color rgba="0.52549 0.52549 0.52549 1.00000"/>
  </material>
</robot>