#VRML_SIM R2023b utf8
# LGDXRobot2 Concept
EXTERNPROTO "https://raw.githubusercontent.com/cyberbotics/webots/R2025a/projects/appearances/protos/Plastic.proto"
EXTERNPROTO "https://raw.githubusercontent.com/cyberbotics/webots/R2025a/projects/appearances/protos/Rubber.proto"
EXTERNPROTO "https://raw.githubusercontent.com/cyberbotics/webots/R2025a/projects/appearances/protos/BrushedAluminium.proto"
PROTO LGDXRobot2 [
  field SFVec3f    translation  0 0 0
  field SFRotation rotation     0 0 1 0
  field SFString   controller   ""
  field SFString   name         ""
]
{
Robot {
  translation IS translation
  rotation IS rotation
  name IS name
  controller IS controller
  children [
    Solid {
      translation 0.1 0 0.05931
      children [
        Accelerometer {
          name "accelerometer"
        }
        Gyro {
          name "gyro"
        }
        InertialUnit {
          name "inertial_unit"
        }
        RangeFinder {
          translation 0.025 0 0.0125
          name "camera depth"
          width 1280
          height 720
        }
        Camera {
          translation 0.025 0 0.0125
          name "camera rgb"
          width 1280
          height 720
        }
        Pose {
          translation 0 0 0.0125
          children [
            Shape {
              appearance BrushedAluminium {
              }
              geometry Mesh {
                url [
                  "../protos/meshes/Camera.dae"
                ]
              }
            }
          ]
        }
      ]
      name "Camera"
      boundingObject Pose {
        translation 0.0125 0 0.0125
        children [
          DEF CAMERA_BO Box {
            size 0.025 0.09 0.025
          }
        ]
      }
      physics Physics {
        density -1
        mass 0.26
      }
    }
    Lidar {
      translation 0.06 0 0.13331
      children [
        DEF LIDAR_BO Pose {
          translation 0 0 0.02065
          children [
            Shape {
              appearance Appearance {
                material Material {
                  transparency 1
                }
              }
              geometry Box {
                size 0.0556 0.0556 0.0413
              }
            }
          ]
        }
        Shape {
          appearance Plastic {
            colorOverride 0 0 0
          }
          geometry Mesh {
            url [
              "meshes/Lidar.dae"
            ]
          }
        }
      ]
      boundingObject USE LIDAR_BO
      physics Physics {
        density -1
        mass 0.11
      }
    }
    HingeJoint {
      jointParameters HingeJointParameters {
        axis 0 1 0
        anchor -0.1055 -0.1025 0.0375
      }
      device [
        RotationalMotor {
          name "wheel4"
        }
        PositionSensor {
          name "encoder4"
        }
      ]
      endPoint Solid {
        translation -0.083 -0.072 0.037
        rotation 1 0 0 1.5708
        children [
          Shape {
            appearance Rubber {
            }
            geometry Mesh {
              url [
                "../protos/meshes/Wheel4.dae"
              ]
            }
          }
        ]
        name "WHEEL_4"
        contactMaterial "ExteriorWheelMat"
        boundingObject Cylinder {
          height 0.095
          radius 0.0375
        }
        physics Physics {
        }
      }
    }
    HingeJoint {
      jointParameters HingeJointParameters {
        axis 0 1 0
        anchor -0.1055 0.1025 0.0375
      }
      device [
        RotationalMotor {
          name "wheel3"
        }
        PositionSensor {
          name "encoder3"
        }
      ]
      endPoint Solid {
        translation -0.083 0.072 0.037
        rotation -0.9999999999999999 0 0 1.5707953071795862
        children [
          Shape {
            appearance Rubber {
            }
            geometry Mesh {
              url [
                "meshes/Wheel3.dae"
              ]
            }
          }
        ]
        name "WHEEL_3"
        contactMaterial "InteriorWheelMat"
        boundingObject Cylinder {
          height 0.095
          radius 0.0375
        }
        physics Physics {
        }
      }
    }
    HingeJoint {
      jointParameters HingeJointParameters {
        axis 0 1 0
        anchor 0.1055 -0.1025 0.0375
      }
      device [
        RotationalMotor {
          name "wheel2"
        }
        PositionSensor {
          name "encoder2"
        }
      ]
      endPoint Solid {
        translation 0.083 -0.072 0.037
        rotation 1 0 0 1.5708
        children [
          Shape {
            appearance Rubber {
            }
            geometry Mesh {
              url [
                "meshes/Wheel2.dae"
              ]
            }
          }
        ]
        name "WHEEL_2"
        contactMaterial "InteriorWheelMat"
        boundingObject Cylinder {
          height 0.095
          radius 0.0375
        }
        physics Physics {
        }
      }
    }
    HingeJoint {
      jointParameters HingeJointParameters {
        axis 0 1 0
        anchor 0.1055 0.1025 0.0375
      }
      device [
        PositionSensor {
          name "encoder1"
        }
        RotationalMotor {
          name "wheel1"
        }
      ]
      endPoint Solid {
        translation 0.083 0.072 0.037
        rotation -1 0 0 1.5708
        children [
          Shape {
            appearance Rubber {
            }
            geometry Mesh {
              url [
                "meshes/Wheel1.dae"
              ]
            }
          }
        ]
        name "WHEEL_1"
        contactMaterial "ExteriorWheelMat"
        boundingObject Cylinder {
          height 0.095
          radius 0.0375
        }
        physics Physics {
        }
      }
    }
    DEF BODY Pose {
      children [
        DEF MOTORS Shape {
          appearance BrushedAluminium {
            IBLStrength 0.5
          }
          geometry Mesh {
            url [
              "meshes/Motors.dae"
            ]
          }
        }
        DEF BRACKETS Shape {
          appearance BrushedAluminium {
            colorOverride 0 0 0
          }
          geometry Mesh {
            url [
              "meshes/Brackets.dae"
            ]
          }
        }
        DEF STANDOFFS Shape {
          appearance BrushedAluminium {
            IBLStrength 0.5
          }
          geometry Mesh {
            url [
              "meshes/Standoffs.dae"
            ]
          }
        }
        DEF PLATES Shape {
          appearance Plastic {
            colorOverride 0.509804 0.105882 0.113725
          }
          geometry Mesh {
            url [
              "meshes/Plates.dae"
            ]
          }
        }
      ]
    }
  ]
  boundingObject Pose {
    translation 0 0 0.094
    children [
      Box {
        size 0.24 0.24 0.078
      }
    ]
  }
  physics Physics {
  }
}
}